<?xml version="1.0"?>
<robot xmlns:xacro="http://www.ros.org/wiki/xacro"  name="robot">
    <material name="white">
        <color rgba="1 1 1 1"/>
    </material>
    <material name="orange">
        <color rgba="1 0.3 0.1 1"/>
    </material>
    <material name="blue">
        <color rgba="0.2 0.2 1 1"/>
    </material>
    <material name="black">
        <color rgba="0 0 0 1"/>
    </material>

    <!-- Base link -->
    <link name="base_link">
        
    </link>

    <!-- Chassis Link -->
    <joint name="chassis_joint" type="fixed">
        <parent link="base_link"/>
        <child link="chassis"/>
        <origin xyz="-0.1 0.0 0.0" rpy="0.0 0.0 0.0"/>
    </joint>

    <link name="chassis">
        <visual>
            <origin xyz="0.3 0 0.1"/>
            <geometry>
                <box size="0.6 0.4 0.2"/>
            </geometry>
            <material name="white"/>
        </visual>
    </link>
    <!-- Left Wheel Link -->

    <joint name="left_wheel_joint" type="continuous">
        <parent link="base_link"/>
        <child link="left_wheel"/>
        <origin xyz="0 0.225 0" rpy="-${pi/2} 0.0 0.0"/>
        <axis xyz="0 0 1"/>
    </joint>

    <link name="left_wheel">
        <visual>
            <geometry>
                <cylinder radius="0.08" length="0.04"/>
            </geometry>
            <material name="blue"></material>
        </visual>
    </link>

        <!-- right Wheel Link -->

        <joint name="right_wheel_joint" type="continuous">
            <parent link="base_link"/>
            <child link="right_wheel"/>
            <origin xyz="0 -0.225 0" rpy="+${pi/2} 0.0 0.0"/>
            <axis xyz="0 0 -1"/>
        </joint>
    
        <link name="right_wheel">
            <visual>
                <geometry>
                    <cylinder radius="0.08" length="0.04"/>
                </geometry>
                <material name="blue"></material>
            </visual>
        </link>
</robot>